Workbook

Sheet Dashboard
C1: PART 101 - MARITIME SECURITY: GENERAL PART F - CYBERSECURITY
A6: This spreadsheet is designed to enter and track data related to Part F assessments.
C7: Grouping | D7: Total Criteria | E7: Lacks | F7: Meets | G7: Exceeds
C8: Owner or Operator | D8: =COUNTIFS(Requirements!A:A, C8, Requirements!C:C, "<>") -> 9 | E8: =COUNTIFS(Requirements!A:A, C8, Requirements!D:D, "Lacks") -> 0 | F8: =COUNTIFS(Requirements!A:A, C8, Requirements!D:D, "Meets") -> 0 | G8: =COUNTIFS(Requirements!A:A, C8, Requirements!D:D, "Exceeds") -> 0
C9: Cybersecurity Officer | D9: =COUNTIFS(Requirements!A:A, C9, Requirements!C:C, "<>") -> 32 | E9: =COUNTIFS(Requirements!A:A, C9, Requirements!D:D, "Lacks") -> 0 | F9: =COUNTIFS(Requirements!A:A, C9, Requirements!D:D, "Meets") -> 0 | G9: =COUNTIFS(Requirements!A:A, C9, Requirements!D:D, "Exceeds") -> 0
C10: Cybersecurity Plan | D10: =COUNTIFS(Requirements!A:A, C10, Requirements!C:C, "<>") -> 41 | E10: =COUNTIFS(Requirements!A:A, C10, Requirements!D:D, "Lacks") -> 0 | F10: =COUNTIFS(Requirements!A:A, C10, Requirements!D:D, "Meets") -> 0 | G10: =COUNTIFS(Requirements!A:A, C10, Requirements!D:D, "Exceeds") -> 0
A11: Tabs | C11: Drills and exercises | D11: =COUNTIFS(Requirements!A:A, C11, Requirements!C:C, "<>") -> 15 | E11: =COUNTIFS(Requirements!A:A, C11, Requirements!D:D, "Lacks") -> 0 | F11: =COUNTIFS(Requirements!A:A, C11, Requirements!D:D, "Meets") -> 0 | G11: =COUNTIFS(Requirements!A:A, C11, Requirements!D:D, "Exceeds") -> 0
A12: Dashboard | B12: This section contains heads up information and visualizations | C12: Records and documentation | D12: =COUNTIFS(Requirements!A:A, C12, Requirements!C:C, "<>") -> 1 | E12: =COUNTIFS(Requirements!A:A, C12, Requirements!D:D, "Lacks") -> 0 | F12: =COUNTIFS(Requirements!A:A, C12, Requirements!D:D, "Meets") -> 0 | G12: =COUNTIFS(Requirements!A:A, C12, Requirements!D:D, "Exceeds") -> 0
A13: Requirments | B13: Part F Requirements | C13: Communications | D13: =COUNTIFS(Requirements!A:A, C13, Requirements!C:C, "<>") -> 2 | E13: =COUNTIFS(Requirements!A:A, C13, Requirements!D:D, "Lacks") -> 0 | F13: =COUNTIFS(Requirements!A:A, C13, Requirements!D:D, "Meets") -> 0 | G13: =COUNTIFS(Requirements!A:A, C13, Requirements!D:D, "Exceeds") -> 0
A14: Vessel Specific Details | B14: Applicable details per Facility | C14: Cybersecurity measures | D14: =COUNTIFS(Requirements!A:A, C14, Requirements!C:C, "<>") -> 57 | E14: =COUNTIFS(Requirements!A:A, C14, Requirements!D:D, "Lacks") -> 0 | F14: =COUNTIFS(Requirements!A:A, C14, Requirements!D:D, "Meets") -> 0 | G14: =COUNTIFS(Requirements!A:A, C14, Requirements!D:D, "Exceeds") -> 0
C15: Total | D15: =SUM(D8:D14) -> 157 | E15: =SUM(E8:E14) -> 0 | F15: =SUM(F8:F14) -> 0 | G15: =SUM(G8:G14) -> 0
E17: Lacks | F17: Meets/Exceeds
E18: =E15 -> 0 | F18: =SUM(F15:G15) -> 0

Sheet Requirements
A1: PART 101 - MARITIME SECURITY: GENERAL PART F - CYBERSECURITY
A7: Group | B7: Section | C7: Control Statement | D7: Eval | E7: Comments
A8: Owner or Operator | B8: 101.620(a) | C8: Owner or operator is responsible for compliance with this subpart.
A9: Owner or Operator | B9: 101.620(b) | C9: For each U.S.-flagged vessel, facility, or OCS facility, the owner or operator must: | L9: Lacks
A10: Owner or Operator | B10: 101.620(b)(1) | C10: Ensure a Cybersecurity Plan is developed, approved, and maintained. | L10: Meets
A11: Owner or Operator | B11: 101.620(b)(2) | C11: Define cybersecurity organizational structure in the Plan, identifying all individuals with duties and ensuring their support. | L11: Exceeds
A12: Owner or Operator | B12: 101.620(b)(3) | C12: Designate a Cybersecurity Officer (CySO) by name/title, accessible 24/7, and provide contact info.
A13: Owner or Operator | B13: 101.620(b)(4) | C13: Ensure cybersecurity exercises, audits, inspections, and the Cybersecurity Assessment are conducted as required.
A14: Owner or Operator | B14: 101.620(b)(5) | C14: Ensure the vessel/facility/OCS facility operates in compliance with the approved Cybersecurity Plan.
A15: Owner or Operator | B15: 101.620(b)(6) | C15: Develop, approve, and execute the Cyber Incident Response Plan.
A16: Owner or Operator | B16: 101.620(b)(7) | C16: If not reporting under 33 CFR 6.16-1, report all reportable cyber incidents to the NRC.
A17: Cybersecurity Officer | B17: 101.625(a) | C17: If the CySO has other duties, verify they can still fulfill CySO responsibilities.
A18: Cybersecurity Officer | B18: 101.625(b) | C18: If one CySO serves multiple entities, list each entity in its Cybersecurity Plan.
A19: Cybersecurity Officer | B19: 101.625(c) | C19: If the CySO assigns duties to others, they retain ultimate responsibility.
A20: Cybersecurity Officer | B20: 101.625(d) | C20: For each U.S.-flagged vessel, facility, or OCS facility for which they are designated, the CySO must:
A21: Cybersecurity Officer | B21: 101.625(d)(1) | C21: Ensure a Cybersecurity Assessment is conducted as required.
A22: Cybersecurity Officer | B22: 101.625(d)(2) | C22: Ensure cybersecurity measures in the Plan are developed, implemented, and operating as intended.
A23: Cybersecurity Officer | B23: 101.625(d)(3) | C23: Ensure the Cybersecurity Plan is audited annually and updated if needed.
... A73: Cybersecurity Plan | B73: 101.630(d)(3) | C73: An approved Cybersecurity Plan is valid for 5 years from the date of approval.
B74: 101.630(e) | C74: Amendments to the Cybersecurity Plan
A75: Cybersecurity Plan | B75: 101.630(e)(1) | C75: Amendments can be initiated by the owner/operator/CySO or required by the Coast Guard.
A76: Cybersecurity Plan | B76: 101.630(e)(1)(i) | C76: Amendments to a Coast Guard-approved Cybersecurity Plan may be initiated by the owner or operator, or the CySO.
A77: Cybersecurity Plan | B77: 101.630(e)(1)(ii) | C77: If the COTP, OCMI, or MSC finds the Plan no longer meets requirements, they will return it with a letter explaining the needed amendments. The owner/operator has at least 60 days to submit proposed amendments. Until approval, temporary measures must be implemented to the satisfaction of the Coast Guard.
A78: Cybersecurity Plan | B78: 101.630(e)(2) | C78: Submit proposed amendments at least 30 days before effective date, unless exigent circumstances apply.
A79: Cybersecurity Plan | B79: 101.630(e)(2)(i) | C79: Nothing in this section limits the owner/operator from implementing additional security measures not enumerated in the approved plan to address exigent security situations.
A80: Cybersecurity Plan | B80: 101.630(e)(2)(ii) | C80: If implementing additional measures, the owner/operator must notify the cognizant COTP (for facilities/OCS facilities) or the MSC (for vessels) by the most rapid means practicable, describing the measures, the circumstances prompting them, and the expected duration.
A81: Cybersecurity Plan | B81: 101.630(e)(3) | C81: If owner/operator changes, amend the Plan within 96 hours with new info.
A82: Cybersecurity Plan | B82: 101.630(e)(4) | C82: If the CySO changes, notify the Coast Guard within 96 hours; amend/submit updated Plan.
B83: 101.630(f) | C83: Audits
A84: Cybersecurity Plan | B84: 101.630(f)(1) | C84: Conduct an annual audit of the Cybersecurity Plan/implementation and attach a certification report.
A85: Cybersecurity Plan | B85: 101.630(f)(2) | C85: Additional audit required if ownership or major security measures change.
A86: Cybersecurity Plan | B86: 101.630(f)(3) | C86: Audit scope can be limited to the updated/affected Plan sections.
A87: Cybersecurity Plan | B87: 101.630(f)(4) | C87: Personnel conducting internal audits of the cybersecurity measures specified in the Plan or evaluating its implementation must
A88: Cybersecurity Plan | B88: 101.630(f)(4)(i) | C88: Have knowledge of methods for conducting audits/inspections, as well as access control and monitoring techniques.
A89: Cybersecurity Plan | B89: 101.630(f)(4)(ii) | C89: Not have regularly assigned cybersecurity duties for the U.S.-flagged vessel, facility, or OCS facility being audited.
A90: Cybersecurity Plan | B90: 101.630(f)(4)(iii) | C90: Be independent of any cybersecurity measures being audited.
A91: Cybersecurity Plan | B91: 101.630(f)(5) | C91: Submit Plan amendments (if needed) within 30 days after audit completion.
B92: 101.635(a) | C92: General
A93: Drills and exercises | B93: 101.635(a)(1) | C93: Drills/exercises must test personnel proficiency and Plan effectiveness.
A94: Drills and exercises | B94: 101.635(a)(2) | C94: An actual cyber incident can satisfy drill requirements if documented exercise goals are met.
...

Sheet Facility Specific Sheet
A1: PART 101 - MARITIME SECURITY: GENERAL PART F - CYBERSECURITY
A6: Vessel Name
A7: Location
A8: Date
A9: Assessor
A10: Main POC
A13: Group | B13: Section | C13: Control Statement | D13: Eval | E13: Comments
A14: Owner or Operator | B14: 101.620(a) | C14: Owner or operator is responsible for compliance with this subpart.
A15: Owner or Operator | B15: 101.620(b) | C15: For each U.S.-flagged vessel, facility, or OCS facility, the owner or operator must: | L15: Lacks
A16: Owner or Operator | B16: 101.620(b)(1) | C16: Ensure a Cybersecurity Plan is developed, approved, and maintained. | L16: Meets
A17: Owner or Operator | B17: 101.620(b)(2) | C17: Define cybersecurity organizational structure in the Plan, identifying all individuals with duties and ensuring their support. | L17: Exceeds
A18: Owner or Operator | B18: 101.620(b)(3) | C18: Designate a Cybersecurity Officer (CySO) by name/title, accessible 24/7, and provide contact info.
A19: Owner or Operator | B19: 101.620(b)(4) | C19: Ensure cybersecurity exercises, audits, inspections, and the Cybersecurity Assessment are conducted as required.
A20: Owner or Operator | B20: 101.620(b)(5) | C20: Ensure the vessel/facility/OCS facility operates in compliance with the approved Cybersecurity Plan.
A21: Owner or Operator | B21: 101.620(b)(6) | C21: Develop, approve, and execute the Cyber Incident Response Plan.
A22: Owner or Operator | B22: 101.620(b)(7) | C22: If not reporting under 33 CFR 6.16-1, report all reportable cyber incidents to the NRC.
A23: Cybersecurity Officer | B23: 101.625(a) | C23: If the CySO has other duties, verify they can still fulfill CySO responsibilities.
A24: Cybersecurity Officer | B24: 101.625(b) | C24: If one CySO serves multiple entities, list each entity in its Cybersecurity Plan.
A25: Cybersecurity Officer | B25: 101.625(c) | C25: If the CySO assigns duties to others, they retain ultimate responsibility.
A26: Cybersecurity Officer | B26: 101.625(d) | C26: For each U.S.-flagged vessel, facility, or OCS facility for which they are designated, the CySO must:
A27: Cybersecurity Officer | B27: 101.625(d)(1) | C27: Ensure a Cybersecurity Assessment is conducted as required.
A28: Cybersecurity Officer | B28: 101.625(d)(2) | C28: Ensure cybersecurity measures in the Plan are developed, implemented, and operating as intended.
A29: Cybersecurity Officer | B29: 101.625(d)(3) | C29: Ensure the Cybersecurity Plan is audited annually and updated if needed.
... A79: Cybersecurity Plan | B79: 101.630(d)(3) | C79: An approved Cybersecurity Plan is valid for 5 years from the date of approval.
B80: 101.630(e) | C80: Amendments to the Cybersecurity Plan
A81: Cybersecurity Plan | B81: 101.630(e)(1) | C81: Amendments can be initiated by the owner/operator/CySO or required by the Coast Guard.
A82: Cybersecurity Plan | B82: 101.630(e)(1)(i) | C82: Amendments to a Coast Guard-approved Cybersecurity Plan may be initiated by the owner or operator, or the CySO.
A83: Cybersecurity Plan | B83: 101.630(e)(1)(ii) | C83: If the COTP, OCMI, or MSC finds the Plan no longer meets requirements, they will return it with a letter explaining the needed amendments. The owner/operator has at least 60 days to submit proposed amendments. Until approval, temporary measures must be implemented to the satisfaction of the Coast Guard.
A84: Cybersecurity Plan | B84: 101.630(e)(2) | C84: Submit proposed amendments at least 30 days before effective date, unless exigent circumstances apply.
A85: Cybersecurity Plan | B85: 101.630(e)(2)(i) | C85: Nothing in this section limits the owner/operator from implementing additional security measures not enumerated in the approved plan to address exigent security situations.
A86: Cybersecurity Plan | B86: 101.630(e)(2)(ii) | C86: If implementing additional measures, the owner/operator must notify the cognizant COTP (for facilities/OCS facilities) or the MSC (for vessels) by the most rapid means practicable, describing the measures, the circumstances prompting them, and the expected duration.
A87: Cybersecurity Plan | B87: 101.630(e)(3) | C87: If owner/operator changes, amend the Plan within 96 hours with new info.
A88: Cybersecurity Plan | B88: 101.630(e)(4) | C88: If the CySO changes, notify the Coast Guard within 96 hours; amend/submit updated Plan.
B89: 101.630(f) | C89: Audits
A90: Cybersecurity Plan | B90: 101.630(f)(1) | C90: Conduct an annual audit of the Cybersecurity Plan/implementation and attach a certification report.
A91: Cybersecurity Plan | B91: 101.630(f)(2) | C91: Additional audit required if ownership or major security measures change.
A92: Cybersecurity Plan | B92: 101.630(f)(3) | C92: Audit scope can be limited to the updated/affected Plan sections.
A93: Cybersecurity Plan | B93: 101.630(f)(4) | C93: Personnel conducting internal audits of the cybersecurity measures specified in the Plan or evaluating its implementation must
A94: Cybersecurity Plan | B94: 101.630(f)(4)(i) | C94: Have knowledge of methods for conducting audits/inspections, as well as access control and monitoring techniques.
A95: Cybersecurity Plan | B95: 101.630(f)(4)(ii) | C95: Not have regularly assigned cybersecurity duties for the U.S.-flagged vessel, facility, or OCS facility being audited.
...
